<?xml version="1.0" ?>
<!-- Generated using onshape-to-robot -->
<!-- Onshape https://cad.onshape.com/documents/9cd2d37f10a20c963aa8c3b1/w/751e7ec4f0185e2cc133f396/e/9a387e7c90ee018179d50e3b -->
<mujoco model="3dofs_model">
  <compiler angle="radian" meshdir="assets" autolimits="true"/>
  <default>
    <default class="3dofs_model">
      <position kp="0.0834356288486003" forcerange="-0.413195026823429 0.413195026823429"/>
      <joint damping="0.030412360296431" frictionloss="0.017508851112988427" armature="0.001102777708135709"/>
      <default class="visual">
        <geom type="mesh" contype="0" conaffinity="0" group="2"/>
      </default>
      <default class="collision">
        <geom group="3"/>
      </default>
    </default>
  </default>
  <worldbody>
    <!-- Link base -->
    <body name="base" pos="0 0 0" quat="1 0 0 0" childclass="3dofs_model">
      <inertial pos="0.0139692 -3.07612e-05 0.0062903" mass="0.0693" fullinertia="7.26197e-05 0.000101787 0.000164149 -9.3971e-08 -1.04905e-05 -6.072e-09"/>
      <!-- Part disk_support -->
      <geom class="collision" pos="-1.3605e-08 0 0.00105" quat="0.707107 0 0 0.707107" type="cylinder" size="0.075 0.00105"/>
      <!-- Part base -->
      <!-- Part xl_320 -->
      <!-- Part base_parts -->
      <geom type="mesh" class="visual" pos="0.0139692 -3.07612e-05 0.0062903" quat="1 0 0 0" mesh="base_visual" material="base_visual_material"/>
      <!-- Link u_part -->
      <body name="u_part" pos="0.0378816 -0 0.0327" quat="0.707107 -0 0 -0.707107">
        <!-- Joint from base to u_part -->
        <joint axis="0 0 1" name="1" type="hinge" range="-2.6179938779914944 2.6179938779914944"/>
        <inertial pos="-7.99857e-05 2.24259e-06 0.00582339" mass="0.00516" fullinertia="7.13166e-07 1.22939e-06 1.09307e-06 -2.2e-11 6.8e-09 -1.91e-10"/>
        <!-- Part u_part -->
        <geom class="collision" pos="0 0 -0.0004" quat="1 0 0 -0" type="cylinder" size="0.0156339 0.0026"/>
        <!-- Part u_part_parts -->
        <geom type="mesh" class="visual" pos="-7.99857e-05 2.24259e-06 0.00582339" quat="0.707107 0 -0 0.707107" mesh="u_part_visual" material="u_part_visual_material"/>
        <!-- Link segment_1 -->
        <body name="segment_1" pos="-0.0149 0 0.0223" quat="0.5 0.5 0.5 0.5">
          <!-- Joint from u_part to segment_1 -->
          <joint axis="0 0 1" name="2" type="hinge" range="-1.570796326794894 1.5707963267948992"/>
          <inertial pos="0 0.049 0.0146105" mass="0.04268" fullinertia="7.27828e-05 4.90297e-06 7.35398e-05 -0 0 0"/>
          <!-- Part plate -->
          <geom class="collision" pos="-0.01315 0.049 0.015" quat="0.5 0.5 -0.5 -0.5" type="box" size="0.055 0.01 0.00115"/>
          <!-- Part xl_320_2 -->
          <!-- Part plate_2 -->
          <geom class="collision" pos="0.01315 0.049 0.015" quat="0.5 0.5 -0.5 -0.5" type="box" size="0.055 0.01 0.00115"/>
          <!-- Part xl_320_3 -->
          <!-- Part segment_1_parts -->
          <geom type="mesh" class="visual" pos="0 0.049 0.0146105" quat="0.707107 -0.707107 -0 0" mesh="segment_1_visual" material="segment_1_visual_material"/>
          <!-- Link end_effector_2 -->
          <body name="end_effector_2" pos="0 0.098 -0" quat="0 -1 0 0">
            <!-- Joint from segment_1 to end_effector_2 -->
            <joint axis="0 0 1" name="3" type="hinge" range="-2.146754979953053 2.146754979952998"/>
            <inertial pos="0.0129719 -0.0435248 -0.014834" mass="0.00579" fullinertia="8.93251e-06 2.81221e-06 1.06042e-05 4.05651e-06 4.958e-09 -1.6637e-08"/>
            <!-- Part end_effector_2 -->
            <geom class="collision" pos="0 -0.0215 -0.0149" quat="0.5 -0.5 -0.5 -0.5" type="box" size="0.0125 0.0039 0.0014"/>
            <geom class="collision" pos="0.0573576 -0.119815 -0.0149" quat="0.5 -0.5 -0.5 -0.5" type="sphere" size="0.005"/>
            <geom class="collision" pos="0 -0.0299 -0.0149" quat="0.5 -0.5 -0.5 -0.5" type="cylinder" size="0.0024 0.0085"/>
            <geom class="collision" pos="0.0277546 -0.0775407 -0.0149" quat="0.627211 -0.326506 -0.627211 -0.326506" type="cylinder" size="0.0024 0.049"/>
            <!-- Part end_effector_2_parts -->
            <geom type="mesh" class="visual" pos="0.0129719 -0.0435248 -0.014834" quat="0.707107 0.707107 -0 -0" mesh="end_effector_2_visual" material="end_effector_2_visual_material"/>
            <!-- Frame end_effector -->
            <site group="3" name="end_effector" pos="0.0573576 -0.119815 -0.0149" quat="0.67438 0.67438 0.212631 0.212631"/>
          </body>
        </body>
      </body>
    </body>
  </worldbody>
  <asset>
    <mesh file="merged/segment_1_visual.stl"/>
    <mesh file="merged/end_effector_2_visual.stl"/>
    <mesh file="merged/base_visual.stl"/>
    <mesh file="merged/u_part_visual.stl"/>
    <material name="base_visual_material" rgba="0.887333 0.753501 0.590471 1"/>
    <material name="u_part_visual_material" rgba="0.615686 0.811765 0.929412 1"/>
    <material name="segment_1_visual_material" rgba="0.683202 0.725836 0.751416 1"/>
    <material name="end_effector_2_visual_material" rgba="0.615686 0.811765 0.929412 1"/>
  </asset>
  <actuator>
    <position class="3dofs_model" name="1" joint="1" ctrlrange="-2.6179938779914944 2.6179938779914944"/>
    <position class="3dofs_model" name="2" joint="2" ctrlrange="-2.6179938779914944 2.6179938779914944"/>
    <position class="3dofs_model" name="3" joint="3" ctrlrange="-2.6179938779914944 2.6179938779914944"/>
  </actuator>
  <equality/>
</mujoco>
